Workbook

Sheet FUNCIONAMENTO
A1: NUMERO | B1: DATA | C1: CONCEPTO | D1: DEBE | E1: HABER | F1: I_G | G1: CODIGO | H1: Cod Decrip | I1: PERIODO | J1: LIBRE | K1: XUSTIFICA | L1: NOME | M1: EUROS | N1: DIA | O1: MES | P1: ANO | Q1: CHEQUE | R1: IMPRIMIR
A2: 0 | B2: 01/01/2022 | C2: SALDO ANTERIOR | E2: 64080.83 | F2: I | G2: H | H2: =VLOOKUP(G2,Codigo!$A$2:$B$46,2,FALSE) -> SALDO ANTERIOR
A3: 1 | B3: 07/01/2025 | C3: GRENKE RENT, S.L.U. | D3: 577.17 | F3: G | G3: 01 | H3: =VLOOKUP(G3,Codigo!$A$2:$B$46,2,FALSE) -> Arredamientos | I3: 1º TRIMESTRE | K3: REPROGRAFIA
A4: 2 | B4: 08/01/2025 | C4: SECURITAS DIRECT | D4: 76.54 | F4: G | G4: 02 | H4: =VLOOKUP(G4,Codigo!$A$2:$B$46,2,FALSE) -> Reparacións | I4: 1º TRIMESTRE | K4: ALARMA
A5: 3 | B5: 08/01/2025 | C5: GRENKE RENT S.L.U. | D5: 126.86 | F5: G | G5: 08 | H5: =VLOOKUP(G5,Codigo!$A$2:$B$46,2,FALSE) -> Prima de seguro | I5: 1º TRIMESTRE | K5: REPROGRAFIA
A6: 4 | B6: 06/02/2025 | C6: SECURITAS DIRECT | D6: 76.54 | F6: G | G6: 02 | H6: =VLOOKUP(G6,Codigo!$A$2:$B$46,2,FALSE) -> Reparacións | I6: 1º TRIMESTRE | K6: ALARMA
A7: 5 | B7: 13/02/2025 | C7: NEUROSINAIS | D7: 120 | F7: G | G7: 11 | H7: =VLOOKUP(G7,Codigo!$A$2:$B$46,2,FALSE) -> Gastos diversos | I7: 1º TRIMESTRE | K7: BECAS NEAE | L7: ANDREA
A8: 6 | B8: 13/02/2025 | C8: NEUROSINAIS | D8: 150 | F8: G | G8: 11 | H8: =VLOOKUP(G8,Codigo!$A$2:$B$46,2,FALSE) -> Gastos diversos | I8: 1º TRIMESTRE | K8: BECAS NEAE | L8: ROI
A9: 7 | B9: 13/02/2025 | C9: MERCACHINA | D9: 11.28 | F9: G | G9: 04.6 | H9: =VLOOKUP(G9,Codigo!$A$2:$B$46,2,FALSE) -> Outras Subministracións | I9: 1º TRIMESTRE | K9: MATERIAL
A10: 8 | B10: 26/02/2025 | C10: NEW CENTER | D10: 10.98 | F10: G | G10: 04.6 | H10: =VLOOKUP(G10,Codigo!$A$2:$B$46,2,FALSE) -> Outras Subministracións | I10: 1º TRIMESTRE
A11: 9 | B11: 26/02/2025 | C11: NEW CENTER | D11: 6.35 | F11: G | G11: 04.6 | H11: =VLOOKUP(G11,Codigo!$A$2:$B$46,2,FALSE) -> Outras Subministracións | I11: 1º TRIMESTRE
A12: 10 | B12: 26/02/2025 | C12: NEW CENTER | D12: 6 | F12: G | G12: 04.6 | H12: =VLOOKUP(G12,Codigo!$A$2:$B$46,2,FALSE) -> Outras Subministracións | I12: 1º TRIMESTRE
A13: 11 | B13: 26/02/2025 | C13: AMAZON | D13: 13.59 | F13: G | G13: 03 | H13: =VLOOKUP(G13,Codigo!$A$2:$B$46,2,FALSE) -> Material de oficina | I13: 1º TRIMESTRE
A14: 12 | B14: 26/02/2025 | C14: AMAZON | D14: 10.9 | F14: G | G14: 03 | H14: =VLOOKUP(G14,Codigo!$A$2:$B$46,2,FALSE) -> Material de oficina | I14: 1º TRIMESTRE
A15: 13 | B15: 26/02/2025 | C15: MIDETERGENTE | D15: 171.24 | F15: G | G15: 11 | H15: =VLOOKUP(G15,Codigo!$A$2:$B$46,2,FALSE) -> Gastos diversos | I15: 1º TRIMESTRE
A16: 14 | B16: 26/02/2025 | C16: A. PINILLA | D16: 375.44 | F16: G | G16: 04.6 | H16: =VLOOKUP(G16,Codigo!$A$2:$B$46,2,FALSE) -> Outras Subministracións | I16: 1º TRIMESTRE
A17: 15 | B17: 26/02/2025 | C17: ANAYA | D17: 21.33 | F17: G | G17: 04.6 | H17: =VLOOKUP(G17,Codigo!$A$2:$B$46,2,FALSE) -> Outras Subministracións | I17: 1º TRIMESTRE | K17: PLAMBE-FONDOS
A18: 16 | B18: 26/02/2025 | C18: VICENS VIVES | D18: 67.97 | F18: G | G18: 04.6 | H18: =VLOOKUP(G18,Codigo!$A$2:$B$46,2,FALSE) -> Outras Subministracións | I18: 2024 | K18: PLAMBE-FONDOS
A19: 17 | B19: 27/02/2025 | C19: ITINERANCIAS FEBREIRO PAMELA | D19: 38.58 | F19: G | G19: 10 | H19: =VLOOKUP(G19,Codigo!$A$2:$B$46,2,FALSE) -> Axudas de custo e locomoción | I19: 1º TRIMESTRE
A20: 18 | B20: 27/02/2025 | C20: ITINERANCIAS FEBREIRO CRISTINA | D20: 38.58 | F20: G | G20: 10 | H20: =VLOOKUP(G20,Codigo!$A$2:$B$46,2,FALSE) -> Axudas de custo e locomoción | I20: 1º TRIMESTRE
A21: 19 | B21: 27/02/2025 | C21: ITINERANCIAS XANEIRO PAMELA | D21: 38.58 | F21: G | G21: 10 | H21: =VLOOKUP(G21,Codigo!$A$2:$B$46,2,FALSE) -> Axudas de custo e locomoción | I21: 1º TRIMESTRE
A22: 20 | B22: 27/02/2025 | C22: ITINERANCIAS XANEIRO CRISTINA | D22: 38.58 | F22: G | G22: 10 | H22: =VLOOKUP(G22,Codigo!$A$2:$B$46,2,FALSE) -> Axudas de custo e locomoción | I22: 1º TRIMESTRE
A23: 21 | B23: 03/03/2025 | C23: CALENDARIOS ESTIÑO | E23: 123 | F23: I | G23: C | H23: =VLOOKUP(G23,Codigo!$A$2:$B$46,2,FALSE) -> Dotacións legados e subvencións | I23: 1º TRIMESTRE
A24: 22 | B24: 06/03/2025 | C24: SECURITAS DIRECT | D24: 76.54 | F24: G | G24: 02 | H24: =VLOOKUP(G24,Codigo!$A$2:$B$46,2,FALSE) -> Reparacións | I24: 1º TRIMESTRE
A25: 23 | B25: 06/03/2025 | C25: ITINERANCIAS FEBREIRO NATI | D25: 22.88 | F25: G | G25: 10 | H25: =VLOOKUP(G25,Codigo!$A$2:$B$46,2,FALSE) -> Axudas de custo e locomoción | I25: 1º TRIMESTRE
A26: 24 | B26: 06/03/2025 | C26: ITINERANCIAS XANEIRO NATI | D26: 22.88 | F26: G | G26: 10 | H26: =VLOOKUP(G26,Codigo!$A$2:$B$46,2,FALSE) -> Axudas de custo e locomoción | I26: 1º TRIMESTRE
A27: 25 | B27: 06/03/2025 | C27: ITINERANCIAS FEBREIRO BEGONA | D27: 22.88 | F27: G | G27: 10 | H27: =VLOOKUP(G27,Codigo!$A$2:$B$46,2,FALSE) -> Axudas de custo e locomoción | I27: 1º TRIMESTRE
A28: 26 | B28: 06/03/2025 | C28: ITINERANCIAS XANEIRO BEGONA | D28: 22.88 | F28: G | G28: 10 | H28: =VLOOKUP(G28,Codigo!$A$2:$B$46,2,FALSE) -> Axudas de custo e locomoción | I28: 1º TRIMESTRE
A29: 27 | B29: 06/03/2025 | C29: CALENDARIOS ESTIÑO | D29: 123 | F29: G | G29: 11 | H29: =VLOOKUP(G29,Codigo!$A$2:$B$46,2,FALSE) -> Gastos diversos | I29: 1º TRIMESTRE
A30: 28 | B30: 13/03/2025 | C30: AMAZON | D30: 28.89 | F30: G | G30: 04.6 | H30: =VLOOKUP(G30,Codigo!$A$2:$B$46,2,FALSE) -> Outras Subministracións | I30: 1º TRIMESTRE
A31: 29 | B31: 13/03/2025 | C31: E.S. GUNTIN | D31: 2866.26 | F31: G | G31: 04.1 | H31: =VLOOKUP(G31,Codigo!$A$2:$B$46,2,FALSE) -> Gasoleo | I31: 1º TRIMESTRE
A32: 30 | B32: 13/03/2025 | C32: NEUROSINAIS | D32: 90 | F32: G | G32: 11 | H32: =VLOOKUP(G32,Codigo!$A$2:$B$46,2,FALSE) -> Gastos diversos | I32: 1º TRIMESTRE | K32: BECAS NEAE | L32: ANDREA
A33: 31 | B33: 13/03/2025 | C33: NEUROSINAIS | D33: 90 | F33: G | G33: 11 | H33: =VLOOKUP(G33,Codigo!$A$2:$B$46,2,FALSE) -> Gastos diversos | I33: 1º TRIMESTRE | K33: BECAS NEAE | L33: ROI
A34: 32 | B34: 31/03/2025 | C34: BOLANDA EDICIONES | D34: 60 | F34: G | G34: 04.6 | H34: =VLOOKUP(G34,Codigo!$A$2:$B$46,2,FALSE) -> Outras Subministracións | I34: 1º TRIMESTRE | K34: PLAMBE-FONDOS
A35: 33 | B35: 31/03/2025 | C35: VIAXE-COMIDA DIRECTOR SANTIAGO 20/0 3/25 | D35: 82 | F35: G | G35: 10 | H35: =VLOOKUP(G35,Codigo!$A$2:$B$46,2,FALSE) -> Axudas de custo e locomoción | I35: 1º TRIMESTRE
A36: 34 | B36: 04/04/2025 | C36: SECURITAS DIRECT | D36: 76.54 | F36: G | G36: 02 | H36: =VLOOKUP(G36,Codigo!$A$2:$B$46,2,FALSE) -> Reparacións | I36: 2º TRIMESTRE
A37: 35 | B37: 04/04/2025 | C37: GRENKE RENT S.L.U. | D37: 577.17 | F37: G | G37: 01 | H37: =VLOOKUP(G37,Codigo!$A$2:$B$46,2,FALSE) -> Arredamientos | I37: 2º TRIMESTRE
A38: 36 | B38: 07/04/2025 | C38: DEPARTAMENTO TERRITORIAL | E38: 8648 | F38: I | G38: A1 | H38: =VLOOKUP(G38,Codigo!$A$2:$B$46,2,FALSE) -> Gastos de funcionamento | I38: 2º TRIMESTRE
A39: 37 | B39: 09/04/2025 | C39: BECA ALUMNO TRASLADADO | E39: 2226 | F39: I | G39: B | H39: =VLOOKUP(G39,Codigo!$A$2:$B$46,2,FALSE) -> Dotacións UE-Outros organismos | I39: 2º TRIMESTRE
A40: 38 | B40: 11/04/2025 | C40: NEUROSINAIS | D40: 60 | F40: G | G40: 11 | H40: =VLOOKUP(G40,Codigo!$A$2:$B$46,2,FALSE) -> Gastos diversos | I40: 1º TRIMESTRE | K40: BECAS NEAE | L40: CANDELA
...

Sheet DEBE
A2: I_G | B2: G
A4: CODIGO | B4: Cod Decrip | C4: PERIODO | D4: CONCEPTO | E4: DATA | F4: NUMERO | G4: DEBE | H4: Suma de DEBE
A5: 01 | B5: Arredamientos | C5: 1º TRIMESTRE | D5: GRENKE RENT, S.L.U. | E5: 07/01/2025 | F5: 1 | G5: 577.17 | H5: 577.17
C6: Total 1º TRIMESTRE | H6: 577.17
C7: 2º TRIMESTRE | D7: ESTURION GALICIA S.L. | E7: 09/06/2025 | F7: 79 | G7: 1294.76 | H7: 1294.76
D8: GRENKE RENT S.L.U. | E8: 04/04/2025 | F8: 35 | G8: 577.17 | H8: 577.17
C9: Total 2º TRIMESTRE | H9: 1871.93
C10: 3º TRIMESTRE | D10: ESTURION GALICIA S.L. | E10: 45849 | F10: 113 | G10: 287.24 | H10: 287.24
E11: 45908 | F11: 120 | G11: 263.84 | H11: 263.84
D12: GRENKE RENT S.L.U. | E12: 45849 | F12: 112 | G12: 577.17 | H12: 577.17
C13: Total 3º TRIMESTRE | H13: 1128.25
C14: 4º TRIMESTRE | D14: ESTURION GALICIA S.L. | E14: 45943 | F14: 133 | G14: 408.19 | H14: 408.19
E15: 45971 | F15: 160 | G15: 408.19 | H15: 408.19
E16: 46002 | F16: 194 | G16: 265.29 | H16: 265.29
C17: Total 4º TRIMESTRE | H17: 1081.67
A18: Total 01 | H18: 4659.02
A19: 02 | B19: Reparacións | C19: 1º TRIMESTRE | D19: SECURITAS DIRECT | E19: 06/02/2025 | F19: 4 | G19: 76.54 | H19: 76.54
E20: 06/03/2025 | F20: 22 | G20: 76.54 | H20: 76.54
E21: 08/01/2025 | F21: 2 | G21: 76.54 | H21: 76.54
C22: Total 1º TRIMESTRE | H22: 229.62
C23: 2º TRIMESTRE | D23: SECURITAS DIRECT | E23: 04/04/2025 | F23: 34 | G23: 76.54 | H23: 76.54
E24: 05/06/2025 | F24: 75 | G24: 76.54 | H24: 76.54
E25: 06/05/2025 | F25: 48 | G25: 76.54 | H25: 76.54
C26: Total 2º TRIMESTRE | H26: 229.62
C27: 3º TRIMESTRE | D27: SECURITAS DIRECT | E27: 45849 | F27: 111 | G27: 76.54 | H27: 76.54
E28: 45897 | F28: 117 | G28: 76.54 | H28: 76.54
E29: 45905 | F29: 119 | G29: 76.54 | H29: 76.54
C30: Total 3º TRIMESTRE | H30: 229.62
C31: 4º TRIMESTRE | D31: PERLADA | E31: 45975 | F31: 171 | G31: 176 | H31: 176
E32: 46021 | F32: 214 | G32: 108 | H32: 108
F33: 215 | G33: 975.5 | H33: 975.5
D34: SECURITAS DIRECT | E34: 45937 | F34: 130 | G34: 12.1 | H34: 12.1
F35: 131 | G35: 76.54 | H35: 76.54
E36: 45971 | F36: 161 | G36: 76.54 | H36: 76.54
E37: 45996 | F37: 192 | G37: 76.54 | H37: 76.54
C38: Total 4º TRIMESTRE | H38: 1501.22
A39: Total 02 | H39: 2190.08
A40: 03 | B40: Material de oficina | C40: 1º TRIMESTRE | D40: AMAZON | E40: 26/02/2025 | F40: 11 | G40: 13.59 | H40: 13.59
F41: 12 | G41: 10.9 | H41: 10.9
E42: 28/06/2025 | F42: 107 | G42: 38.24 | H42: 38.24
...

Sheet HABER
A2: I_G | B2: I
A4: CODIGO | B4: Cod Decrip | C4: PERIODO | D4: CONCEPTO | E4: DATA | F4: NUMERO | G4: HABER | H4: Suma de HABER
A5: A1 | B5: Gastos de funcionamento | C5: 2º TRIMESTRE | D5: DEPARTAMENTO TERRITORIAL | E5: 07/04/2025 | F5: 36 | G5: 8648 | H5: 8648
E6: 13/06/2025 | F6: 96 | G6: 6486 | H6: 6486
C7: Total 2º TRIMESTRE | H7: 15134
C8: 4º TRIMESTRE | D8: DEPARTAMENTO TERRITORIAL | E8: 45966 | F8: 152 | G8: 6486 | H8: 6486
E9: 46021 | F9: 210 | G9: 6558 | H9: 6558
C10: Total 4º TRIMESTRE | H10: 13044
A11: Total A1 | H11: 28178
A12: B | B12: Dotacións UE-Outros organismos | C12: 2º TRIMESTRE | D12: BECA ALUMNO TRASLADADO | E12: 09/04/2025 | F12: 37 | G12: 2226 | H12: 2226
C13: Total 2º TRIMESTRE | H13: 2226
C14: 4º TRIMESTRE | D14: BECAS S G TESORO | E14: 45966 | F14: 153 | G14: 1313 | H14: 1313
F15: 154 | G15: 400 | H15: 400
F16: 155 | G16: 2226 | H16: 2226
F17: 156 | G17: 400 | H17: 400
F18: 157 | G18: 400 | H18: 400
C19: Total 4º TRIMESTRE | H19: 4739
A20: Total B | H20: 6965
A21: C | B21: Dotacións legados e subvencións | C21: 1º TRIMESTRE | D21: CALENDARIOS ESTIÑO | E21: 03/03/2025 | F21: 21 | G21: 123 | H21: 123
C22: Total 1º TRIMESTRE | H22: 123
C23: 2º TRIMESTRE | D23: 2º ABONO LUCUS AVENTUR 3º/4º | E23: 05/06/2025 | F23: 76 | G23: 624 | H23: 624
D24: AUTOBUS 1º CICLO | E24: 19/05/2025 | F24: 59 | G24: 308 | H24: 308
D25: AUTOBÚS 3º/4º (BILLETES) | E25: 05/06/2025 | F25: 78 | G25: 320 | H25: 320
D26: AUTOBÚS 3º/4º (MOEDAS) | E26: 12/06/2025 | F26: 88 | G26: 137 | H26: 137
D27: AUTOBUS E. INFANTIL | E27: 05/06/2025 | F27: 77 | G27: 550 | H27: 550
D28: EXCUR. 5º LUCUS AVENTUR | E28: 19/05/2025 | F28: 58 | G28: 1015 | H28: 1015
D29: RESERVA LUCUS AVENTUR | E29: 19/05/2025 | F29: 60 | G29: 624 | H29: 624
C30: Total 2º TRIMESTRE | H30: 3578
C31: 4º TRIMESTRE | D31: EXCURSION GALIPARK 2º CICLO | E31: 45958 | F31: 149 | G31: 841 | H31: 841
E32: 45966 | F32: 151 | G32: 861 | H32: 861
C33: Total 4º TRIMESTRE | H33: 1702
A34: Total C | H34: 5403
A35: H | B35: SALDO ANTERIOR | D35: SALDO ANTERIOR | E35: 01/01/2022 | F35: 0 | G35: 64080.83 | H35: 64080.83
C36: Total | H36: 64080.83
A37: Total H | H37: 64080.83
A38: A3 | B38: Dotación Biblioteca | C38: 4º TRIMESTRE | D38: DEPARTAMENTO TERRITORIAL | E38: 45966 | F38: 158 | G38: 1030 | H38: 1030
C39: Total 4º TRIMESTRE | H39: 1030
A40: Total A3 | H40: 1030
A41: A2 | B41: Fondo solidario libros | C41: 4º TRIMESTRE | D41: FONDO SOLIDARIO DE LIBROS EDIXGAL | E41: 45978 | F41: 175 | G41: 4320 | H41: 4320
E42: 46055 | F42: 225 | G42: 80 | H42: 80
...

Sheet BALANCE
C2: BALANCE
A3: TOTAL
C4: DEBE | D4: =VLOOKUP("Total general",DEBE!A5:H1000,8,FALSE) -> 65985.68
C5: HABER | D5: =VLOOKUP("Total general",HABER!A5:H1000,8,FALSE) -> 113014
C7: RESULTADO | D7: =D5-D4 -> 47028.32

Sheet Codigo
A1: CÓDIGO | B1: DESCRIPCION
A2: 01 | B2: Arredamientos
A3: 02 | B3: Reparacións
A4: 03 | B4: Material de oficina
A5: 04 | B5: Suministracións
A6: 04.1 | B6: Gasoleo
A7: 04.2 | B7: Gas
A8: 04.3 | B8: Biomasa/Pellets
A9: 04.4 | B9: Electricidade
A10: 04.5 | B10: Auga
A11: 04.6 | B11: Outras Subministracións
A12: 05 | B12: Comunicacións
... A41: L | B41: Outros ingresos
